Workbook

Sheet Start Here
B1: Money Tracker
B2: Income | Budgets | Daily Spending | Insights - all amounts in Kenya Shillings (KES)
B4: HOW TO USE IT - 5 SIMPLE STEPS
B5: 1 | C5: Settings | D5: Look at the lists once (categories, payment methods, income sources) and rename them to suit you.
B6: 2 | C6: Budget | D6: For each category choose Daily, Weekly or Monthly and type the amount. Set it once - it repeats every month by itself.
B7: 3 | C7: Income | D7: Every time money comes in, add a row: date, source, amount.
B8: 4 | C8: Transactions | D8: Every time you spend, add a row: date, time, item, category, amount, how you paid.
B9: 5 | C9: Dashboard | D9: Pick the Year and Month at the top to see totals, overspending alerts, weekly, daily and category analysis.
B11: FINDING THINGS
B12: Search sheet: filter by date range, product name, category or time of day and see matching transactions and their total instantly. Transactions & Income sheets: use the small filter arrows on row 4 to sort or filter by any column.
B14: Open the Search sheet
B16: COLOUR GUIDE
C17: Yellow cell, blue text | D17: You type here.
C18: White / grey cell | D18: Automatic - formulas live here, please don't type over them.
B19: OK | C19: Green | D19: Within budget.
B20: Watch | C20: Amber | D20: Close to the limit (default: 80% of budget used - change on Settings).
B21: OVER | C21: Red | D21: You are overspending.
B23: WHAT A ROW LOOKS LIKE (EXAMPLE)
B24: Time | C24: Date | D24: Item / Product | E24: Category | F24: Amount (KES) | G24: Paid With
B25: 1:15 PM | C25: 46321 | D25: Lunch at Java House | E25: Eating Out | F25: 1450 | G25: M-Pesa
B27: HANDY SHORTCUTS
C28: Ctrl + ; | D28: type today's date
C29: Ctrl + Shift + ; | D29: type the current time
C30: Alt + Down Arrow | D30: open a dropdown list in the selected cell
C31: Ctrl + D | D31: copy the cell above into the selected cell
B33: GOOD TO KNOW
B34: - | C34: Capacity: 5,000 transactions, 2,000 income entries and 40 budget lines. Plenty for a year or more of daily use.
B35: - | C35: Budgets are not tied to a month: set once, they apply to every month. Use the Starts/Ends columns to keep history when a budget changes.
B36: - | C36: Overspending alerts: total budget, each category, each week and each day are checked automatically. The Dashboard banner tells you in plain words where you stand.
B37: - | C37: Savings, chama contributions or loan repayments count as money going out - give them a category (e.g. 'Loans & Debt') if you want them budgeted.
B38: - | C38: The Dashboard and Year View are protected so formulas can't be damaged by accident (Review > Unprotect Sheet - no password).
B39: - | C39: Back up often: save a copy of this file at month-end (File > Save a Copy).
B41: ALL SHEETS
C42: Dashboard | D42: Totals, alerts, charts and analysis for any month
C43: Transactions | D43: Your daily spending log
C44: Income | D44: Where your money comes from
C45: Budget | D45: Daily, weekly or monthly budgets per category
C46: Search | D46: Find any transaction by date, time, product or category
C47: Year View | D47: Month-by-month overview for the whole year
C48: Settings | D48: Categories, payment methods, income sources and alert level

Sheet Dashboard
B1: Personal Finance Dashboard
B2: ="Analysis for "&TEXT(PeriodStart,"mmmm yyyy")&" | All amounts in Kenya Shillings (KES)" -> Analysis for October 2026 | All amounts in Kenya Shillings (KES)
B3: Choose the period to analyse: | C3: Year | D3: Month
B4: Use the two dropdowns | C4: 2026 | D4: October | F4: =IF(IsCurrent=1,"Current month: day "&DaysElapsed&" of "&DaysInMonth&" ("&DaysLeft&" days to go)",IF(PeriodEnd<TODAY(),"Past month - full results","Future month - nothing to analyse yet")) -> Current month: day 27 of 31 (4 days to go)
B6: TOTAL INCOME | D6: TOTAL SPENT | F6: NET SAVINGS | H6: SAVINGS RATE | J6: BUDGET USED | L6: BUDGET STATUS
B7: =SUMIFS(Income!$D$5:$D$2004,Income!$A$5:$A$2004,">="&PeriodStart,Income!$A$5:$A$2004,"<="&PeriodEnd) -> 0 | D7: =SUMIFS(Transactions!$E$5:$E$5004,Transactions!$A$5:$A$5004,">="&PeriodStart,Transactions!$A$5:$A$5004,"<="&PeriodEnd) -> 0 | F7: =B7-D7 -> 0 | H7: =IF(B7=0,0,F7/B7) -> 0 | J7: =IF(C13=0,0,D7/C13) -> 0 | L7: =IF(C13=0,"NO BUDGET",IF(D7>C13,"OVERSPENDING",IF(J7>=WarnPct,"WATCH OUT","ON TRACK"))) -> NO BUDGET
B8: =COUNTIFS(Income!$A$5:$A$2004,">="&PeriodStart,Income!$A$5:$A$2004,"<="&PeriodEnd)&" income entries" -> 0 income entries | D8: =COUNTIFS(Transactions!$A$5:$A$5004,">="&PeriodStart,Transactions!$A$5:$A$5004,"<="&PeriodEnd)&" transactions" -> 0 transactions | F8: =IF(F7>=0,"Income minus spending","Spending is above income") -> Income minus spending | H8: =IF(B7=0,"No income recorded",IF(H7>=0.2,"Healthy saving habit",IF(H7>=0,"Room to improve","Spending exceeds income"))) -> No income recorded | J8: ="of KES "&TEXT(C13,"#,##0")&" budget" -> of KES 0 budget | L8: =IF(C13=0,"Add budgets to track",IF(D7>C13,"Over by KES "&TEXT(D7-C13,"#,##0"),"KES "&TEXT(C13-D7,"#,##0")&" left")) -> Add budgets to track
B10: =IF(C13=0,"No budget set yet - add your budgets on the Budget sheet to switch on overspending alerts.",IF(C14>C13,"OVERSPENDING: you have spent KES "&TEXT(C14-C13,"#,##0")&" more than your total budget for this period."&IF(C22>0," Watch out: "&C22&IF(C22=1," category is"," categories are")&" over its own budget.",""),IF(AND(IsCurrent=1,C16>0,C17>0.1*C16),"HEADS UP: you are spending faster than planned. At this pace you will finish near KES "&TEXT(C18,"#,##0")&" against a budget of KES "&TEXT(C13,"#,##0")&"."&IF(C22>0," Watch out: "&C22&IF(C22=1," category is"," categories are")&" over its own budget.",""),"ON TRACK: you are within budget."&IF(IsCurrent=1," You can spend about KES "&TEXT(C20,"#,##0")&" per day for the rest of the month.","")&IF(C22>0," Watch out: "&C22&IF(C22=1," category is"," categories are")&" over its own budget.","")))) -> No budget set yet - add your budgets on the Budget sheet to switch on overspending alerts.
B12: SPENDING HEALTH | E12: WEEKLY BREAKDOWN
B13: Total budget for the month | C13: =C42 -> 0 | E13: Week | F13: Dates | G13: Spent | H13: Budget | I13: Status
B14: Spent so far | C14: =D7 -> 0 | E14: Week 1 | F14: =IF((PeriodStart+7*0)>PeriodEnd,"",TEXT((PeriodStart+7*0),"d mmm")&" - "&TEXT(MIN(PeriodEnd,PeriodStart+7*1-1),"d mmm")) -> 1 Oct - 7 Oct | G14: =IF($F14="","",SUMIFS(Transactions!$E$5:$E$5004,Transactions!$A$5:$A$5004,">="&(PeriodStart+7*0),Transactions!$A$5:$A$5004,"<="&MIN(PeriodEnd,PeriodStart+7*1-1))) -> 0 | H14: =IF($F14="","",$C$13*(MIN(PeriodEnd,PeriodStart+7*1-1)-(PeriodStart+7*0)+1)/DaysInMonth) -> 0 | I14: =IF($F14="","",IF((PeriodStart+7*0)>TODAY(),"Upcoming",IF(H14=0,IF(G14>0,"No budget","-"),IF(G14>H14,"OVER",IF(G14>=WarnPct*H14,"Watch","OK"))))) -> -
B15: Budget remaining | C15: =C13-C14 -> 0 | E15: Week 2 | F15: =IF((PeriodStart+7*1)>PeriodEnd,"",TEXT((PeriodStart+7*1),"d mmm")&" - "&TEXT(MIN(PeriodEnd,PeriodStart+7*2-1),"d mmm")) -> 8 Oct - 14 Oct | G15: =IF($F15="","",SUMIFS(Transactions!$E$5:$E$5004,Transactions!$A$5:$A$5004,">="&(PeriodStart+7*1),Transactions!$A$5:$A$5004,"<="&MIN(PeriodEnd,PeriodStart+7*2-1))) -> 0 | H15: =IF($F15="","",$C$13*(MIN(PeriodEnd,PeriodStart+7*2-1)-(PeriodStart+7*1)+1)/DaysInMonth) -> 0 | I15: =IF($F15="","",IF((PeriodStart+7*1)>TODAY(),"Upcoming",IF(H15=0,IF(G15>0,"No budget","-"),IF(G15>H15,"OVER",IF(G15>=WarnPct*H15,"Watch","OK"))))) -> -
B16: Expected spend by today (pace) | C16: =IF(IsCurrent=1,C13*DaysElapsed/DaysInMonth,IF(PeriodEnd<TODAY(),C13,0)) -> 0 | E16: Week 3 | F16: =IF((PeriodStart+7*2)>PeriodEnd,"",TEXT((PeriodStart+7*2),"d mmm")&" - "&TEXT(MIN(PeriodEnd,PeriodStart+7*3-1),"d mmm")) -> 15 Oct - 21 Oct | G16: =IF($F16="","",SUMIFS(Transactions!$E$5:$E$5004,Transactions!$A$5:$A$5004,">="&(PeriodStart+7*2),Transactions!$A$5:$A$5004,"<="&MIN(PeriodEnd,PeriodStart+7*3-1))) -> 0 | H16: =IF($F16="","",$C$13*(MIN(PeriodEnd,PeriodStart+7*3-1)-(PeriodStart+7*2)+1)/DaysInMonth) -> 0 | I16: =IF($F16="","",IF((PeriodStart+7*2)>TODAY(),"Upcoming",IF(H16=0,IF(G16>0,"No budget","-"),IF(G16>H16,"OVER",IF(G16>=WarnPct*H16,"Watch","OK"))))) -> -
B17: Ahead (+) / behind (-) of pace | C17: =IF(C13=0,0,C14-C16) -> 0 | E17: Week 4 | F17: =IF((PeriodStart+7*3)>PeriodEnd,"",TEXT((PeriodStart+7*3),"d mmm")&" - "&TEXT(MIN(PeriodEnd,PeriodStart+7*4-1),"d mmm")) -> 22 Oct - 28 Oct | G17: =IF($F17="","",SUMIFS(Transactions!$E$5:$E$5004,Transactions!$A$5:$A$5004,">="&(PeriodStart+7*3),Transactions!$A$5:$A$5004,"<="&MIN(PeriodEnd,PeriodStart+7*4-1))) -> 0 | H17: =IF($F17="","",$C$13*(MIN(PeriodEnd,PeriodStart+7*4-1)-(PeriodStart+7*3)+1)/DaysInMonth) -> 0 | I17: =IF($F17="","",IF((PeriodStart+7*3)>TODAY(),"Upcoming",IF(H17=0,IF(G17>0,"No budget","-"),IF(G17>H17,"OVER",IF(G17>=WarnPct*H17,"Watch","OK"))))) -> -
B18: Projected month-end spend | C18: =IF(IsCurrent=1,IF(DaysElapsed=0,0,C14/DaysElapsed*DaysInMonth),C14) -> 0 | E18: Week 5 | F18: =IF((PeriodStart+7*4)>PeriodEnd,"",TEXT((PeriodStart+7*4),"d mmm")&" - "&TEXT(MIN(PeriodEnd,PeriodStart+7*5-1),"d mmm")) -> 29 Oct - 31 Oct | G18: =IF($F18="","",SUMIFS(Transactions!$E$5:$E$5004,Transactions!$A$5:$A$5004,">="&(PeriodStart+7*4),Transactions!$A$5:$A$5004,"<="&MIN(PeriodEnd,PeriodStart+7*5-1))) -> 0 | H18: =IF($F18="","",$C$13*(MIN(PeriodEnd,PeriodStart+7*5-1)-(PeriodStart+7*4)+1)/DaysInMonth) -> 0 | I18: =IF($F18="","",IF((PeriodStart+7*4)>TODAY(),"Upcoming",IF(H18=0,IF(G18>0,"No budget","-"),IF(G18>H18,"OVER",IF(G18>=WarnPct*H18,"Watch","OK"))))) -> Upcoming
B19: Projected over (+) / under (-) budget | C19: =IF(C13=0,0,C18-C13) -> 0 | E19: Total | G19: =SUM(G14:G18) -> 0 | H19: =SUM(H14:H18) -> 0
B20: Safe to spend per day (rest of month) | C20: =IF(AND(IsCurrent=1,DaysLeft>0),MAX(C15,0)/DaysLeft,0) -> 0
B21: Average spend per day | C21: =IF(DaysElapsed=0,0,C14/DaysElapsed) -> 0 | E21: Weekly budget = your monthly budget spread evenly across the days of each week.
B22: Categories over budget | C22: =COUNTIF(G26:G41,"OVER") -> 0
B24: BUDGET vs ACTUAL BY CATEGORY
B25: Category | C25: Budget | D25: Spent | E25: Remaining | F25: % Used | G25: Status
B26: =IF(Settings!$B$6="","",Settings!$B$6) -> Food & Groceries | C26: =IF($B26="","",SUMPRODUCT((Budget!$A$5:$A$44=$B26)*Budget!$C$5:$C$44*((Budget!$B$5:$B$44="Monthly")+(Budget!$B$5:$B$44="Daily")*DaysInMonth+(Budget!$B$5:$B$44="Weekly")*DaysInMonth/7)*(Budget!$D$5:$D$44<=PeriodEnd)*(((Budget!$E$5:$E$44="")+(Budget!$E$5:$E$44>=PeriodStart))>0))) -> 0 | D26: =IF($B26="","",SUMIFS(Transactions!$E$5:$E$5004,Transactions!$D$5:$D$5004,$B26,Transactions!$A$5:$A$5004,">="&PeriodStart,Transactions!$A$5:$A$5004,"<="&PeriodEnd)) -> 0 | E26: =IF($B26="","",C26-D26) -> 0 | F26: =IF($B26="","",IF(C26=0,0,D26/C26)) -> 0 | G26: =IF($B26="","",IF(C26=0,IF(D26>0,"No budget","-"),IF(D26>C26,"OVER",IF(D26>=WarnPct*C26,"Watch","OK")))) -> -
B27: =IF(Settings!$B$7="","",Settings!$B$7) -> Eating Out | C27: =IF($B27="","",SUMPRODUCT((Budget!$A$5:$A$44=$B27)*Budget!$C$5:$C$44*((Budget!$B$5:$B$44="Monthly")+(Budget!$B$5:$B$44="Daily")*DaysInMonth+(Budget!$B$5:$B$44="Weekly")*DaysInMonth/7)*(Budget!$D$5:$D$44<=PeriodEnd)*(((Budget!$E$5:$E$44="")+(Budget!$E$5:$E$44>=PeriodStart))>0))) -> 0 | D27: =IF($B27="","",SUMIFS(Transactions!$E$5:$E$5004,Transactions!$D$5:$D$5004,$B27,Transactions!$A$5:$A$5004,">="&PeriodStart,Transactions!$A$5:$A$5004,"<="&PeriodEnd)) -> 0 | E27: =IF($B27="","",C27-D27) -> 0 | F27: =IF($B27="","",IF(C27=0,0,D27/C27)) -> 0 | G27: =IF($B27="","",IF(C27=0,IF(D27>0,"No budget","-"),IF(D27>C27,"OVER",IF(D27>=WarnPct*C27,"Watch","OK")))) -> -
B28: =IF(Settings!$B$8="","",Settings!$B$8) -> Rent & Housing | C28: =IF($B28="","",SUMPRODUCT((Budget!$A$5:$A$44=$B28)*Budget!$C$5:$C$44*((Budget!$B$5:$B$44="Monthly")+(Budget!$B$5:$B$44="Daily")*DaysInMonth+(Budget!$B$5:$B$44="Weekly")*DaysInMonth/7)*(Budget!$D$5:$D$44<=PeriodEnd)*(((Budget!$E$5:$E$44="")+(Budget!$E$5:$E$44>=PeriodStart))>0))) -> 0 | D28: =IF($B28="","",SUMIFS(Transactions!$E$5:$E$5004,Transactions!$D$5:$D$5004,$B28,Transactions!$A$5:$A$5004,">="&PeriodStart,Transactions!$A$5:$A$5004,"<="&PeriodEnd)) -> 0 | E28: =IF($B28="","",C28-D28) -> 0 | F28: =IF($B28="","",IF(C28=0,0,D28/C28)) -> 0 | G28: =IF($B28="","",IF(C28=0,IF(D28>0,"No budget","-"),IF(D28>C28,"OVER",IF(D28>=WarnPct*C28,"Watch","OK")))) -> -
B29: =IF(Settings!$B$9="","",Settings!$B$9) -> Utilities | C29: =IF($B29="","",SUMPRODUCT((Budget!$A$5:$A$44=$B29)*Budget!$C$5:$C$44*((Budget!$B$5:$B$44="Monthly")+(Budget!$B$5:$B$44="Daily")*DaysInMonth+(Budget!$B$5:$B$44="Weekly")*DaysInMonth/7)*(Budget!$D$5:$D$44<=PeriodEnd)*(((Budget!$E$5:$E$44="")+(Budget!$E$5:$E$44>=PeriodStart))>0))) -> 0 | D29: =IF($B29="","",SUMIFS(Transactions!$E$5:$E$5004,Transactions!$D$5:$D$5004,$B29,Transactions!$A$5:$A$5004,">="&PeriodStart,Transactions!$A$5:$A$5004,"<="&PeriodEnd)) -> 0 | E29: =IF($B29="","",C29-D29) -> 0 | F29: =IF($B29="","",IF(C29=0,0,D29/C29)) -> 0 | G29: =IF($B29="","",IF(C29=0,IF(D29>0,"No budget","-"),IF(D29>C29,"OVER",IF(D29>=WarnPct*C29,"Watch","OK")))) -> -
B30: =IF(Settings!$B$10="","",Settings!$B$10) -> Transport & Fuel | C30: =IF($B30="","",SUMPRODUCT((Budget!$A$5:$A$44=$B30)*Budget!$C$5:$C$44*((Budget!$B$5:$B$44="Monthly")+(Budget!$B$5:$B$44="Daily")*DaysInMonth+(Budget!$B$5:$B$44="Weekly")*DaysInMonth/7)*(Budget!$D$5:$D$44<=PeriodEnd)*(((Budget!$E$5:$E$44="")+(Budget!$E$5:$E$44>=PeriodStart))>0))) -> 0 | D30: =IF($B30="","",SUMIFS(Transactions!$E$5:$E$5004,Transactions!$D$5:$D$5004,$B30,Transactions!$A$5:$A$5004,">="&PeriodStart,Transactions!$A$5:$A$5004,"<="&PeriodEnd)) -> 0 | E30: =IF($B30="","",C30-D30) -> 0 | F30: =IF($B30="","",IF(C30=0,0,D30/C30)) -> 0 | G30: =IF($B30="","",IF(C30=0,IF(D30>0,"No budget","-"),IF(D30>C30,"OVER",IF(D30>=WarnPct*C30,"Watch","OK")))) -> -
B31: =IF(Settings!$B$11="","",Settings!$B$11) -> Airtime & Data | C31: =IF($B31="","",SUMPRODUCT((Budget!$A$5:$A$44=$B31)*Budget!$C$5:$C$44*((Budget!$B$5:$B$44="Monthly")+(Budget!$B$5:$B$44="Daily")*DaysInMonth+(Budget!$B$5:$B$44="Weekly")*DaysInMonth/7)*(Budget!$D$5:$D$44<=PeriodEnd)*(((Budget!$E$5:$E$44="")+(Budget!$E$5:$E$44>=PeriodStart))>0))) -> 0 | D31: =IF($B31="","",SUMIFS(Transactions!$E$5:$E$5004,Transactions!$D$5:$D$5004,$B31,Transactions!$A$5:$A$5004,">="&PeriodStart,Transactions!$A$5:$A$5004,"<="&PeriodEnd)) -> 0 | E31: =IF($B31="","",C31-D31) -> 0 | F31: =IF($B31="","",IF(C31=0,0,D31/C31)) -> 0 | G31: =IF($B31="","",IF(C31=0,IF(D31>0,"No budget","-"),IF(D31>C31,"OVER",IF(D31>=WarnPct*C31,"Watch","OK")))) -> -
B32: =IF(Settings!$B$12="","",Settings!$B$12) -> Health & Medical | C32: =IF($B32="","",SUMPRODUCT((Budget!$A$5:$A$44=$B32)*Budget!$C$5:$C$44*((Budget!$B$5:$B$44="Monthly")+(Budget!$B$5:$B$44="Daily")*DaysInMonth+(Budget!$B$5:$B$44="Weekly")*DaysInMonth/7)*(Budget!$D$5:$D$44<=PeriodEnd)*(((Budget!$E$5:$E$44="")+(Budget!$E$5:$E$44>=PeriodStart))>0))) -> 0 | D32: =IF($B32="","",SUMIFS(Transactions!$E$5:$E$5004,Transactions!$D$5:$D$5004,$B32,Transactions!$A$5:$A$5004,">="&PeriodStart,Transactions!$A$5:$A$5004,"<="&PeriodEnd)) -> 0 | E32: =IF($B32="","",C32-D32) -> 0 | F32: =IF($B32="","",IF(C32=0,0,D32/C32)) -> 0 | G32: =IF($B32="","",IF(C32=0,IF(D32>0,"No budget","-"),IF(D32>C32,"OVER",IF(D32>=WarnPct*C32,"Watch","OK")))) -> -
B33: =IF(Settings!$B$13="","",Settings!$B$13) -> Education & School Fees | C33: =IF($B33="","",SUMPRODUCT((Budget!$A$5:$A$44=$B33)*Budget!$C$5:$C$44*((Budget!$B$5:$B$44="Monthly")+(Budget!$B$5:$B$44="Daily")*DaysInMonth+(Budget!$B$5:$B$44="Weekly")*DaysInMonth/7)*(Budget!$D$5:$D$44<=PeriodEnd)*(((Budget!$E$5:$E$44="")+(Budget!$E$5:$E$44>=PeriodStart))>0))) -> 0 | D33: =IF($B33="","",SUMIFS(Transactions!$E$5:$E$5004,Transactions!$D$5:$D$5004,$B33,Transactions!$A$5:$A$5004,">="&PeriodStart,Transactions!$A$5:$A$5004,"<="&PeriodEnd)) -> 0 | E33: =IF($B33="","",C33-D33) -> 0 | F33: =IF($B33="","",IF(C33=0,0,D33/C33)) -> 0 | G33: =IF($B33="","",IF(C33=0,IF(D33>0,"No budget","-"),IF(D33>C33,"OVER",IF(D33>=WarnPct*C33,"Watch","OK")))) -> -
B34: =IF(Settings!$B$14="","",Settings!$B$14) -> Business Expenses | C34: =IF($B34="","",SUMPRODUCT((Budget!$A$5:$A$44=$B34)*Budget!$C$5:$C$44*((Budget!$B$5:$B$44="Monthly")+(Budget!$B$5:$B$44="Daily")*DaysInMonth+(Budget!$B$5:$B$44="Weekly")*DaysInMonth/7)*(Budget!$D$5:$D$44<=PeriodEnd)*(((Budget!$E$5:$E$44="")+(Budget!$E$5:$E$44>=PeriodStart))>0))) -> 0 | D34: =IF($B34="","",SUMIFS(Transactions!$E$5:$E$5004,Transactions!$D$5:$D$5004,$B34,Transactions!$A$5:$A$5004,">="&PeriodStart,Transactions!$A$5:$A$5004,"<="&PeriodEnd)) -> 0 | E34: =IF($B34="","",C34-D34) -> 0 | F34: =IF($B34="","",IF(C34=0,0,D34/C34)) -> 0 | G34: =IF($B34="","",IF(C34=0,IF(D34>0,"No budget","-"),IF(D34>C34,"OVER",IF(D34>=WarnPct*C34,"Watch","OK")))) -> -
B35: =IF(Settings!$B$15="","",Settings!$B$15) -> Shopping & Clothing | C35: =IF($B35="","",SUMPRODUCT((Budget!$A$5:$A$44=$B35)*Budget!$C$5:$C$44*((Budget!$B$5:$B$44="Monthly")+(Budget!$B$5:$B$44="Daily")*DaysInMonth+(Budget!$B$5:$B$44="Weekly")*DaysInMonth/7)*(Budget!$D$5:$D$44<=PeriodEnd)*(((Budget!$E$5:$E$44="")+(Budget!$E$5:$E$44>=PeriodStart))>0))) -> 0 | D35: =IF($B35="","",SUMIFS(Transactions!$E$5:$E$5004,Transactions!$D$5:$D$5004,$B35,Transactions!$A$5:$A$5004,">="&PeriodStart,Transactions!$A$5:$A$5004,"<="&PeriodEnd)) -> 0 | E35: =IF($B35="","",C35-D35) -> 0 | F35: =IF($B35="","",IF(C35=0,0,D35/C35)) -> 0 | G35: =IF($B35="","",IF(C35=0,IF(D35>0,"No budget","-"),IF(D35>C35,"OVER",IF(D35>=WarnPct*C35,"Watch","OK")))) -> -
B36: =IF(Settings!$B$16="","",Settings!$B$16) -> Entertainment & Leisure | C36: =IF($B36="","",SUMPRODUCT((Budget!$A$5:$A$44=$B36)*Budget!$C$5:$C$44*((Budget!$B$5:$B$44="Monthly")+(Budget!$B$5:$B$44="Daily")*DaysInMonth+(Budget!$B$5:$B$44="Weekly")*DaysInMonth/7)*(Budget!$D$5:$D$44<=PeriodEnd)*(((Budget!$E$5:$E$44="")+(Budget!$E$5:$E$44>=PeriodStart))>0))) -> 0 | D36: =IF($B36="","",SUMIFS(Transactions!$E$5:$E$5004,Transactions!$D$5:$D$5004,$B36,Transactions!$A$5:$A$5004,">="&PeriodStart,Transactions!$A$5:$A$5004,"<="&PeriodEnd)) -> 0 | E36: =IF($B36="","",C36-D36) -> 0 | F36: =IF($B36="","",IF(C36=0,0,D36/C36)) -> 0 | G36: =IF($B36="","",IF(C36=0,IF(D36>0,"No budget","-"),IF(D36>C36,"OVER",IF(D36>=WarnPct*C36,"Watch","OK")))) -> -
B37: =IF(Settings!$B$17="","",Settings!$B$17) -> Personal Care | C37: =IF($B37="","",SUMPRODUCT((Budget!$A$5:$A$44=$B37)*Budget!$C$5:$C$44*((Budget!$B$5:$B$44="Monthly")+(Budget!$B$5:$B$44="Daily")*DaysInMonth+(Budget!$B$5:$B$44="Weekly")*DaysInMonth/7)*(Budget!$D$5:$D$44<=PeriodEnd)*(((Budget!$E$5:$E$44="")+(Budget!$E$5:$E$44>=PeriodStart))>0))) -> 0 | D37: =IF($B37="","",SUMIFS(Transactions!$E$5:$E$5004,Transactions!$D$5:$D$5004,$B37,Transactions!$A$5:$A$5004,">="&PeriodStart,Transactions!$A$5:$A$5004,"<="&PeriodEnd)) -> 0 | E37: =IF($B37="","",C37-D37) -> 0 | F37: =IF($B37="","",IF(C37=0,0,D37/C37)) -> 0 | G37: =IF($B37="","",IF(C37=0,IF(D37>0,"No budget","-"),IF(D37>C37,"OVER",IF(D37>=WarnPct*C37,"Watch","OK")))) -> -
B38: =IF(Settings!$B$18="","",Settings!$B$18) -> Family & Support | C38: =IF($B38="","",SUMPRODUCT((Budget!$A$5:$A$44=$B38)*Budget!$C$5:$C$44*((Budget!$B$5:$B$44="Monthly")+(Budget!$B$5:$B$44="Daily")*DaysInMonth+(Budget!$B$5:$B$44="Weekly")*DaysInMonth/7)*(Budget!$D$5:$D$44<=PeriodEnd)*(((Budget!$E$5:$E$44="")+(Budget!$E$5:$E$44>=PeriodStart))>0))) -> 0 | D38: =IF($B38="","",SUMIFS(Transactions!$E$5:$E$5004,Transactions!$D$5:$D$5004,$B38,Transactions!$A$5:$A$5004,">="&PeriodStart,Transactions!$A$5:$A$5004,"<="&PeriodEnd)) -> 0 | E38: =IF($B38="","",C38-D38) -> 0 | F38: =IF($B38="","",IF(C38=0,0,D38/C38)) -> 0 | G38: =IF($B38="","",IF(C38=0,IF(D38>0,"No budget","-"),IF(D38>C38,"OVER",IF(D38>=WarnPct*C38,"Watch","OK")))) -> -
B39: =IF(Settings!$B$19="","",Settings!$B$19) -> Giving & Church | C39: =IF($B39="","",SUMPRODUCT((Budget!$A$5:$A$44=$B39)*Budget!$C$5:$C$44*((Budget!$B$5:$B$44="Monthly")+(Budget!$B$5:$B$44="Daily")*DaysInMonth+(Budget!$B$5:$B$44="Weekly")*DaysInMonth/7)*(Budget!$D$5:$D$44<=PeriodEnd)*(((Budget!$E$5:$E$44="")+(Budget!$E$5:$E$44>=PeriodStart))>0))) -> 0 | D39: =IF($B39="","",SUMIFS(Transactions!$E$5:$E$5004,Transactions!$D$5:$D$5004,$B39,Transactions!$A$5:$A$5004,">="&PeriodStart,Transactions!$A$5:$A$5004,"<="&PeriodEnd)) -> 0 | E39: =IF($B39="","",C39-D39) -> 0 | F39: =IF($B39="","",IF(C39=0,0,D39/C39)) -> 0 | G39: =IF($B39="","",IF(C39=0,IF(D39>0,"No budget","-"),IF(D39>C39,"OVER",IF(D39>=WarnPct*C39,"Watch","OK")))) -> -
B40: =IF(Settings!$B$20="","",Settings!$B$20) -> Loans & Debt | C40: =IF($B40="","",SUMPRODUCT((Budget!$A$5:$A$44=$B40)*Budget!$C$5:$C$44*((Budget!$B$5:$B$44="Monthly")+(Budget!$B$5:$B$44="Daily")*DaysInMonth+(Budget!$B$5:$B$44="Weekly")*DaysInMonth/7)*(Budget!$D$5:$D$44<=PeriodEnd)*(((Budget!$E$5:$E$44="")+(Budget!$E$5:$E$44>=PeriodStart))>0))) -> 0 | D40: =IF($B40="","",SUMIFS(Transactions!$E$5:$E$5004,Transactions!$D$5:$D$5004,$B40,Transactions!$A$5:$A$5004,">="&PeriodStart,Transactions!$A$5:$A$5004,"<="&PeriodEnd)) -> 0 | E40: =IF($B40="","",C40-D40) -> 0 | F40: =IF($B40="","",IF(C40=0,0,D40/C40)) -> 0 | G40: =IF($B40="","",IF(C40=0,IF(D40>0,"No budget","-"),IF(D40>C40,"OVER",IF(D40>=WarnPct*C40,"Watch","OK")))) -> -
B41: =IF(Settings!$B$21="","",Settings!$B$21) -> Other | C41: =IF($B41="","",SUMPRODUCT((Budget!$A$5:$A$44=$B41)*Budget!$C$5:$C$44*((Budget!$B$5:$B$44="Monthly")+(Budget!$B$5:$B$44="Daily")*DaysInMonth+(Budget!$B$5:$B$44="Weekly")*DaysInMonth/7)*(Budget!$D$5:$D$44<=PeriodEnd)*(((Budget!$E$5:$E$44="")+(Budget!$E$5:$E$44>=PeriodStart))>0))) -> 0 | D41: =IF($B41="","",SUMIFS(Transactions!$E$5:$E$5004,Transactions!$D$5:$D$5004,$B41,Transactions!$A$5:$A$5004,">="&PeriodStart,Transactions!$A$5:$A$5004,"<="&PeriodEnd)) -> 0 | E41: =IF($B41="","",C41-D41) -> 0 | F41: =IF($B41="","",IF(C41=0,0,D41/C41)) -> 0 | G41: =IF($B41="","",IF(C41=0,IF(D41>0,"No budget","-"),IF(D41>C41,"OVER",IF(D41>=WarnPct*C41,"Watch","OK")))) -> -
B42: TOTAL | C42: =SUM(C26:C41) -> 0 | D42: =SUM(D26:D41) -> 0 | E42: =C42-D42 -> 0 | F42: =IF(C42=0,0,D42/C42) -> 0 | G42: =IF(C42=0,"-",IF(D42>C42,"OVER",IF(D42>=WarnPct*C42,"Watch","OK"))) -> -
B45: INCOME BY SOURCE | F45: SPENDING BY PAYMENT METHOD
B46: Source | C46: Amount (KES) | D46: Share | F46: Method | G46: Amount (KES) | H46: Share
...

Sheet Transactions
A1: Daily Transactions
A2: Record every spend on its own row the day it happens. Shortcuts: Ctrl+; = today's date | Ctrl+Shift+; = current time | Alt+Down Arrow = open a dropdown. Use the filter arrows on row 4 to find anything by date, time or item.
A3: Records: | B3: =COUNT(E5:E5004) -> 0 | C3: Total recorded (all dates, KES): | D3: =SUM(E5:E5004) -> 0
A4: Date | B4: Time | C4: Item / Product | D4: Category | E4: Amount (KES) | F4: Paid With | G4: Notes | H4: match # | I4: match amt | J4: top key
H5: =N(H4)+IFERROR(IF(AND($A5<>"",$E5<>"",$A5>=IF(Search!$E$4="",0,Search!$E$4),$A5<=IF(Search!$E$5="",99999,Search!$E$5),OR(Search!$E$6="",ISNUMBER(SEARCH(Search!$E$6,$C5))),OR(Search!$E$7="All",Search!$E$7="",$D5=Search!$E$7),OR(Search!$E$8="",Search!$E$9="",AND($B5<>"",MOD($B5,1)>=Search!$E$8,MOD($B5,1)<=Search!$E$9))),1,0),0) -> 0 | I5: =IF(H5>N(H4),$E5,0) -> 0 | J5: =IFERROR(IF(AND($A5<>"",$E5<>"",$A5>=PeriodStart,$A5<=PeriodEnd),$E5+ROW()/1000000,0),0) -> 0
H6: =N(H5)+IFERROR(IF(AND($A6<>"",$E6<>"",$A6>=IF(Search!$E$4="",0,Search!$E$4),$A6<=IF(Search!$E$5="",99999,Search!$E$5),OR(Search!$E$6="",ISNUMBER(SEARCH(Search!$E$6,$C6))),OR(Search!$E$7="All",Search!$E$7="",$D6=Search!$E$7),OR(Search!$E$8="",Search!$E$9="",AND($B6<>"",MOD($B6,1)>=Search!$E$8,MOD($B6,1)<=Search!$E$9))),1,0),0) -> 0 | I6: =IF(H6>N(H5),$E6,0) -> 0 | J6: =IFERROR(IF(AND($A6<>"",$E6<>"",$A6>=PeriodStart,$A6<=PeriodEnd),$E6+ROW()/1000000,0),0) -> 0
H7: =N(H6)+IFERROR(IF(AND($A7<>"",$E7<>"",$A7>=IF(Search!$E$4="",0,Search!$E$4),$A7<=IF(Search!$E$5="",99999,Search!$E$5),OR(Search!$E$6="",ISNUMBER(SEARCH(Search!$E$6,$C7))),OR(Search!$E$7="All",Search!$E$7="",$D7=Search!$E$7),OR(Search!$E$8="",Search!$E$9="",AND($B7<>"",MOD($B7,1)>=Search!$E$8,MOD($B7,1)<=Search!$E$9))),1,0),0) -> 0 | I7: =IF(H7>N(H6),$E7,0) -> 0 | J7: =IFERROR(IF(AND($A7<>"",$E7<>"",$A7>=PeriodStart,$A7<=PeriodEnd),$E7+ROW()/1000000,0),0) -> 0
H8: =N(H7)+IFERROR(IF(AND($A8<>"",$E8<>"",$A8>=IF(Search!$E$4="",0,Search!$E$4),$A8<=IF(Search!$E$5="",99999,Search!$E$5),OR(Search!$E$6="",ISNUMBER(SEARCH(Search!$E$6,$C8))),OR(Search!$E$7="All",Search!$E$7="",$D8=Search!$E$7),OR(Search!$E$8="",Search!$E$9="",AND($B8<>"",MOD($B8,1)>=Search!$E$8,MOD($B8,1)<=Search!$E$9))),1,0),0) -> 0 | I8: =IF(H8>N(H7),$E8,0) -> 0 | J8: =IFERROR(IF(AND($A8<>"",$E8<>"",$A8>=PeriodStart,$A8<=PeriodEnd),$E8+ROW()/1000000,0),0) -> 0
H9: =N(H8)+IFERROR(IF(AND($A9<>"",$E9<>"",$A9>=IF(Search!$E$4="",0,Search!$E$4),$A9<=IF(Search!$E$5="",99999,Search!$E$5),OR(Search!$E$6="",ISNUMBER(SEARCH(Search!$E$6,$C9))),OR(Search!$E$7="All",Search!$E$7="",$D9=Search!$E$7),OR(Search!$E$8="",Search!$E$9="",AND($B9<>"",MOD($B9,1)>=Search!$E$8,MOD($B9,1)<=Search!$E$9))),1,0),0) -> 0 | I9: =IF(H9>N(H8),$E9,0) -> 0 | J9: =IFERROR(IF(AND($A9<>"",$E9<>"",$A9>=PeriodStart,$A9<=PeriodEnd),$E9+ROW()/1000000,0),0) -> 0
H10: =N(H9)+IFERROR(IF(AND($A10<>"",$E10<>"",$A10>=IF(Search!$E$4="",0,Search!$E$4),$A10<=IF(Search!$E$5="",99999,Search!$E$5),OR(Search!$E$6="",ISNUMBER(SEARCH(Search!$E$6,$C10))),OR(Search!$E$7="All",Search!$E$7="",$D10=Search!$E$7),OR(Search!$E$8="",Search!$E$9="",AND($B10<>"",MOD($B10,1)>=Search!$E$8,MOD($B10,1)<=Search!$E$9))),1,0),0) -> 0 | I10: =IF(H10>N(H9),$E10,0) -> 0 | J10: =IFERROR(IF(AND($A10<>"",$E10<>"",$A10>=PeriodStart,$A10<=PeriodEnd),$E10+ROW()/1000000,0),0) -> 0
H11: =N(H10)+IFERROR(IF(AND($A11<>"",$E11<>"",$A11>=IF(Search!$E$4="",0,Search!$E$4),$A11<=IF(Search!$E$5="",99999,Search!$E$5),OR(Search!$E$6="",ISNUMBER(SEARCH(Search!$E$6,$C11))),OR(Search!$E$7="All",Search!$E$7="",$D11=Search!$E$7),OR(Search!$E$8="",Search!$E$9="",AND($B11<>"",MOD($B11,1)>=Search!$E$8,MOD($B11,1)<=Search!$E$9))),1,0),0) -> 0 | I11: =IF(H11>N(H10),$E11,0) -> 0 | J11: =IFERROR(IF(AND($A11<>"",$E11<>"",$A11>=PeriodStart,$A11<=PeriodEnd),$E11+ROW()/1000000,0),0) -> 0
H12: =N(H11)+IFERROR(IF(AND($A12<>"",$E12<>"",$A12>=IF(Search!$E$4="",0,Search!$E$4),$A12<=IF(Search!$E$5="",99999,Search!$E$5),OR(Search!$E$6="",ISNUMBER(SEARCH(Search!$E$6,$C12))),OR(Search!$E$7="All",Search!$E$7="",$D12=Search!$E$7),OR(Search!$E$8="",Search!$E$9="",AND($B12<>"",MOD($B12,1)>=Search!$E$8,MOD($B12,1)<=Search!$E$9))),1,0),0) -> 0 | I12: =IF(H12>N(H11),$E12,0) -> 0 | J12: =IFERROR(IF(AND($A12<>"",$E12<>"",$A12>=PeriodStart,$A12<=PeriodEnd),$E12+ROW()/1000000,0),0) -> 0
H13: =N(H12)+IFERROR(IF(AND($A13<>"",$E13<>"",$A13>=IF(Search!$E$4="",0,Search!$E$4),$A13<=IF(Search!$E$5="",99999,Search!$E$5),OR(Search!$E$6="",ISNUMBER(SEARCH(Search!$E$6,$C13))),OR(Search!$E$7="All",Search!$E$7="",$D13=Search!$E$7),OR(Search!$E$8="",Search!$E$9="",AND($B13<>"",MOD($B13,1)>=Search!$E$8,MOD($B13,1)<=Search!$E$9))),1,0),0) -> 0 | I13: =IF(H13>N(H12),$E13,0) -> 0 | J13: =IFERROR(IF(AND($A13<>"",$E13<>"",$A13>=PeriodStart,$A13<=PeriodEnd),$E13+ROW()/1000000,0),0) -> 0
H14: =N(H13)+IFERROR(IF(AND($A14<>"",$E14<>"",$A14>=IF(Search!$E$4="",0,Search!$E$4),$A14<=IF(Search!$E$5="",99999,Search!$E$5),OR(Search!$E$6="",ISNUMBER(SEARCH(Search!$E$6,$C14))),OR(Search!$E$7="All",Search!$E$7="",$D14=Search!$E$7),OR(Search!$E$8="",Search!$E$9="",AND($B14<>"",MOD($B14,1)>=Search!$E$8,MOD($B14,1)<=Search!$E$9))),1,0),0) -> 0 | I14: =IF(H14>N(H13),$E14,0) -> 0 | J14: =IFERROR(IF(AND($A14<>"",$E14<>"",$A14>=PeriodStart,$A14<=PeriodEnd),$E14+ROW()/1000000,0),0) -> 0
H15: =N(H14)+IFERROR(IF(AND($A15<>"",$E15<>"",$A15>=IF(Search!$E$4="",0,Search!$E$4),$A15<=IF(Search!$E$5="",99999,Search!$E$5),OR(Search!$E$6="",ISNUMBER(SEARCH(Search!$E$6,$C15))),OR(Search!$E$7="All",Search!$E$7="",$D15=Search!$E$7),OR(Search!$E$8="",Search!$E$9="",AND($B15<>"",MOD($B15,1)>=Search!$E$8,MOD($B15,1)<=Search!$E$9))),1,0),0) -> 0 | I15: =IF(H15>N(H14),$E15,0) -> 0 | J15: =IFERROR(IF(AND($A15<>"",$E15<>"",$A15>=PeriodStart,$A15<=PeriodEnd),$E15+ROW()/1000000,0),0) -> 0
H16: =N(H15)+IFERROR(IF(AND($A16<>"",$E16<>"",$A16>=IF(Search!$E$4="",0,Search!$E$4),$A16<=IF(Search!$E$5="",99999,Search!$E$5),OR(Search!$E$6="",ISNUMBER(SEARCH(Search!$E$6,$C16))),OR(Search!$E$7="All",Search!$E$7="",$D16=Search!$E$7),OR(Search!$E$8="",Search!$E$9="",AND($B16<>"",MOD($B16,1)>=Search!$E$8,MOD($B16,1)<=Search!$E$9))),1,0),0) -> 0 | I16: =IF(H16>N(H15),$E16,0) -> 0 | J16: =IFERROR(IF(AND($A16<>"",$E16<>"",$A16>=PeriodStart,$A16<=PeriodEnd),$E16+ROW()/1000000,0),0) -> 0
... H1004: =N(H1003)+IFERROR(IF(AND($A1004<>"",$E1004<>"",$A1004>=IF(Search!$E$4="",0,Search!$E$4),$A1004<=IF(Search!$E$5="",99999,Search!$E$5),OR(Search!$E$6="",ISNUMBER(SEARCH(Search!$E$6,$C1004))),OR(Search!$E$7="All",Search!$E$7="",$D1004=Search!$E$7),OR(Search!$E$8="",Search!$E$9="",AND($B1004<>"",MOD($B1004,1)>=Search!$E$8,MOD($B1004,1)<=Search!$E$9))),1,0),0) -> 0 | I1004: =IF(H1004>N(H1003),$E1004,0) -> 0 | J1004: =IFERROR(IF(AND($A1004<>"",$E1004<>"",$A1004>=PeriodStart,$A1004<=PeriodEnd),$E1004+ROW()/1000000,0),0) -> 0

Sheet Income
A1: Income Sources & Receipts
A2: Record every payment you receive - salary, client payments, side income, gifts. Pick the source from the dropdown (edit the list on the Settings sheet).
A3: Entries: | B3: =COUNT(D5:D2004) -> 0 | C3: Total income recorded (all dates, KES): | D3: =SUM(D5:D2004) -> 0
A4: Date | B4: Income Source | C4: Description | D4: Amount (KES) | E4: Received Via | F4: Notes

Sheet Budget
A1: Budgets
A2: Set a budget ONCE and it repeats automatically every month. Choose Daily, Weekly or Monthly and type the amount. Need to change a budget later without altering past months? Put an 'Ends' date on the old line and add a new line with a 'Starts' date.
E3: All lines combined: | F3: =SUM(F5:F44) -> 0 | G3: =SUM(G5:G44) -> 0 | H3: =SUM(H5:H44) -> 0
A4: Category | B4: Budget Period | C4: Budget Amount (KES) | D4: Starts (optional) | E4: Ends (optional) | F4: Per Day | G4: Per Week | H4: Per Month (avg)
A5: =Settings!$B$6 -> Food & Groceries | B5: Monthly | F5: =IF(OR($C5="",$B5=""),"",IF($B5="Daily",$C5,IF($B5="Weekly",$C5/7,$C5*12/365))) | G5: =IF($F5="","",$F5*7) | H5: =IF($F5="","",$F5*365/12)
A6: =Settings!$B$7 -> Eating Out | B6: Monthly | F6: =IF(OR($C6="",$B6=""),"",IF($B6="Daily",$C6,IF($B6="Weekly",$C6/7,$C6*12/365))) | G6: =IF($F6="","",$F6*7) | H6: =IF($F6="","",$F6*365/12)
A7: =Settings!$B$8 -> Rent & Housing | B7: Monthly | F7: =IF(OR($C7="",$B7=""),"",IF($B7="Daily",$C7,IF($B7="Weekly",$C7/7,$C7*12/365))) | G7: =IF($F7="","",$F7*7) | H7: =IF($F7="","",$F7*365/12)
A8: =Settings!$B$9 -> Utilities | B8: Monthly | F8: =IF(OR($C8="",$B8=""),"",IF($B8="Daily",$C8,IF($B8="Weekly",$C8/7,$C8*12/365))) | G8: =IF($F8="","",$F8*7) | H8: =IF($F8="","",$F8*365/12)
A9: =Settings!$B$10 -> Transport & Fuel | B9: Monthly | F9: =IF(OR($C9="",$B9=""),"",IF($B9="Daily",$C9,IF($B9="Weekly",$C9/7,$C9*12/365))) | G9: =IF($F9="","",$F9*7) | H9: =IF($F9="","",$F9*365/12)
A10: =Settings!$B$11 -> Airtime & Data | B10: Monthly | F10: =IF(OR($C10="",$B10=""),"",IF($B10="Daily",$C10,IF($B10="Weekly",$C10/7,$C10*12/365))) | G10: =IF($F10="","",$F10*7) | H10: =IF($F10="","",$F10*365/12)
A11: =Settings!$B$12 -> Health & Medical | B11: Monthly | F11: =IF(OR($C11="",$B11=""),"",IF($B11="Daily",$C11,IF($B11="Weekly",$C11/7,$C11*12/365))) | G11: =IF($F11="","",$F11*7) | H11: =IF($F11="","",$F11*365/12)
A12: =Settings!$B$13 -> Education & School Fees | B12: Monthly | F12: =IF(OR($C12="",$B12=""),"",IF($B12="Daily",$C12,IF($B12="Weekly",$C12/7,$C12*12/365))) | G12: =IF($F12="","",$F12*7) | H12: =IF($F12="","",$F12*365/12)
A13: =Settings!$B$14 -> Business Expenses | B13: Monthly | F13: =IF(OR($C13="",$B13=""),"",IF($B13="Daily",$C13,IF($B13="Weekly",$C13/7,$C13*12/365))) | G13: =IF($F13="","",$F13*7) | H13: =IF($F13="","",$F13*365/12)
A14: =Settings!$B$15 -> Shopping & Clothing | B14: Monthly | F14: =IF(OR($C14="",$B14=""),"",IF($B14="Daily",$C14,IF($B14="Weekly",$C14/7,$C14*12/365))) | G14: =IF($F14="","",$F14*7) | H14: =IF($F14="","",$F14*365/12)
A15: =Settings!$B$16 -> Entertainment & Leisure | B15: Monthly | F15: =IF(OR($C15="",$B15=""),"",IF($B15="Daily",$C15,IF($B15="Weekly",$C15/7,$C15*12/365))) | G15: =IF($F15="","",$F15*7) | H15: =IF($F15="","",$F15*365/12)
A16: =Settings!$B$17 -> Personal Care | B16: Monthly | F16: =IF(OR($C16="",$B16=""),"",IF($B16="Daily",$C16,IF($B16="Weekly",$C16/7,$C16*12/365))) | G16: =IF($F16="","",$F16*7) | H16: =IF($F16="","",$F16*365/12)
A17: =Settings!$B$18 -> Family & Support | B17: Monthly | F17: =IF(OR($C17="",$B17=""),"",IF($B17="Daily",$C17,IF($B17="Weekly",$C17/7,$C17*12/365))) | G17: =IF($F17="","",$F17*7) | H17: =IF($F17="","",$F17*365/12)
A18: =Settings!$B$19 -> Giving & Church | B18: Monthly | F18: =IF(OR($C18="",$B18=""),"",IF($B18="Daily",$C18,IF($B18="Weekly",$C18/7,$C18*12/365))) | G18: =IF($F18="","",$F18*7) | H18: =IF($F18="","",$F18*365/12)
A19: =Settings!$B$20 -> Loans & Debt | B19: Monthly | F19: =IF(OR($C19="",$B19=""),"",IF($B19="Daily",$C19,IF($B19="Weekly",$C19/7,$C19*12/365))) | G19: =IF($F19="","",$F19*7) | H19: =IF($F19="","",$F19*365/12)
A20: =Settings!$B$21 -> Other | B20: Monthly | F20: =IF(OR($C20="",$B20=""),"",IF($B20="Daily",$C20,IF($B20="Weekly",$C20/7,$C20*12/365))) | G20: =IF($F20="","",$F20*7) | H20: =IF($F20="","",$F20*365/12)
F21: =IF(OR($C21="",$B21=""),"",IF($B21="Daily",$C21,IF($B21="Weekly",$C21/7,$C21*12/365))) | G21: =IF($F21="","",$F21*7) | H21: =IF($F21="","",$F21*365/12)
F22: =IF(OR($C22="",$B22=""),"",IF($B22="Daily",$C22,IF($B22="Weekly",$C22/7,$C22*12/365))) | G22: =IF($F22="","",$F22*7) | H22: =IF($F22="","",$F22*365/12)
F23: =IF(OR($C23="",$B23=""),"",IF($B23="Daily",$C23,IF($B23="Weekly",$C23/7,$C23*12/365))) | G23: =IF($F23="","",$F23*7) | H23: =IF($F23="","",$F23*365/12)
F24: =IF(OR($C24="",$B24=""),"",IF($B24="Daily",$C24,IF($B24="Weekly",$C24/7,$C24*12/365))) | G24: =IF($F24="","",$F24*7) | H24: =IF($F24="","",$F24*365/12)
F25: =IF(OR($C25="",$B25=""),"",IF($B25="Daily",$C25,IF($B25="Weekly",$C25/7,$C25*12/365))) | G25: =IF($F25="","",$F25*7) | H25: =IF($F25="","",$F25*365/12)
F26: =IF(OR($C26="",$B26=""),"",IF($B26="Daily",$C26,IF($B26="Weekly",$C26/7,$C26*12/365))) | G26: =IF($F26="","",$F26*7) | H26: =IF($F26="","",$F26*365/12)
F27: =IF(OR($C27="",$B27=""),"",IF($B27="Daily",$C27,IF($B27="Weekly",$C27/7,$C27*12/365))) | G27: =IF($F27="","",$F27*7) | H27: =IF($F27="","",$F27*365/12)
F28: =IF(OR($C28="",$B28=""),"",IF($B28="Daily",$C28,IF($B28="Weekly",$C28/7,$C28*12/365))) | G28: =IF($F28="","",$F28*7) | H28: =IF($F28="","",$F28*365/12)
F29: =IF(OR($C29="",$B29=""),"",IF($B29="Daily",$C29,IF($B29="Weekly",$C29/7,$C29*12/365))) | G29: =IF($F29="","",$F29*7) | H29: =IF($F29="","",$F29*365/12)
F30: =IF(OR($C30="",$B30=""),"",IF($B30="Daily",$C30,IF($B30="Weekly",$C30/7,$C30*12/365))) | G30: =IF($F30="","",$F30*7) | H30: =IF($F30="","",$F30*365/12)
F31: =IF(OR($C31="",$B31=""),"",IF($B31="Daily",$C31,IF($B31="Weekly",$C31/7,$C31*12/365))) | G31: =IF($F31="","",$F31*7) | H31: =IF($F31="","",$F31*365/12)
F32: =IF(OR($C32="",$B32=""),"",IF($B32="Daily",$C32,IF($B32="Weekly",$C32/7,$C32*12/365))) | G32: =IF($F32="","",$F32*7) | H32: =IF($F32="","",$F32*365/12)
... F44: =IF(OR($C44="",$B44=""),"",IF($B44="Daily",$C44,IF($B44="Weekly",$C44/7,$C44*12/365))) | G44: =IF($F44="","",$F44*7) | H44: =IF($F44="","",$F44*365/12)

Sheet Search
B1: Search Transactions
B2: Fill in any of the yellow boxes - leave the rest empty. Results appear below instantly.
C4: From date | F4: Leave empty for 'any date'
C5: To date | F5: Leave empty for 'any date'
C6: Product / item contains | F6: Type part of the name, e.g. 'naivas' or 'uber'
C7: Category | E7: All | F7: Pick a category or 'All'
C8: Time from | F8: Optional - e.g. 6:00 PM (use with 'Time to')
C9: Time to | F9: Optional - e.g. 11:30 PM
C11: Matches found | E11: =MAX(Transactions!$H$5:$H$5004) -> 0 | F11: =IF(E11>100,"Showing the first 100 matches - narrow your search to see the rest.",IF(E11=0,"No transactions match these filters.","Showing all matches.")) -> No transactions match these filters.
C12: Total amount (KES) | E12: =SUM(Transactions!$I$5:$I$5004) -> 0
B14: # | C14: Date | D14: Time | E14: Item / Product | F14: Category | G14: Amount (KES) | H14: Paid With | I14: Notes
B15: =IF($K15="","",1) | C15: =IF($K15="","",IF(INDEX(Transactions!$A$5:$A$5004,$K15)="","",INDEX(Transactions!$A$5:$A$5004,$K15))) | D15: =IF($K15="","",IF(INDEX(Transactions!$B$5:$B$5004,$K15)="","",INDEX(Transactions!$B$5:$B$5004,$K15))) | E15: =IF($K15="","",IF(INDEX(Transactions!$C$5:$C$5004,$K15)="","",INDEX(Transactions!$C$5:$C$5004,$K15))) | F15: =IF($K15="","",IF(INDEX(Transactions!$D$5:$D$5004,$K15)="","",INDEX(Transactions!$D$5:$D$5004,$K15))) | G15: =IF($K15="","",IF(INDEX(Transactions!$E$5:$E$5004,$K15)="","",INDEX(Transactions!$E$5:$E$5004,$K15))) | H15: =IF($K15="","",IF(INDEX(Transactions!$F$5:$F$5004,$K15)="","",INDEX(Transactions!$F$5:$F$5004,$K15))) | I15: =IF($K15="","",IF(INDEX(Transactions!$G$5:$G$5004,$K15)="","",INDEX(Transactions!$G$5:$G$5004,$K15))) | K15: =IFERROR(MATCH(1,Transactions!$H$5:$H$5004,0),"")
B16: =IF($K16="","",2) | C16: =IF($K16="","",IF(INDEX(Transactions!$A$5:$A$5004,$K16)="","",INDEX(Transactions!$A$5:$A$5004,$K16))) | D16: =IF($K16="","",IF(INDEX(Transactions!$B$5:$B$5004,$K16)="","",INDEX(Transactions!$B$5:$B$5004,$K16))) | E16: =IF($K16="","",IF(INDEX(Transactions!$C$5:$C$5004,$K16)="","",INDEX(Transactions!$C$5:$C$5004,$K16))) | F16: =IF($K16="","",IF(INDEX(Transactions!$D$5:$D$5004,$K16)="","",INDEX(Transactions!$D$5:$D$5004,$K16))) | G16: =IF($K16="","",IF(INDEX(Transactions!$E$5:$E$5004,$K16)="","",INDEX(Transactions!$E$5:$E$5004,$K16))) | H16: =IF($K16="","",IF(INDEX(Transactions!$F$5:$F$5004,$K16)="","",INDEX(Transactions!$F$5:$F$5004,$K16))) | I16: =IF($K16="","",IF(INDEX(Transactions!$G$5:$G$5004,$K16)="","",INDEX(Transactions!$G$5:$G$5004,$K16))) | K16: =IFERROR(MATCH(2,Transactions!$H$5:$H$5004,0),"")
B17: =IF($K17="","",3) | C17: =IF($K17="","",IF(INDEX(Transactions!$A$5:$A$5004,$K17)="","",INDEX(Transactions!$A$5:$A$5004,$K17))) | D17: =IF($K17="","",IF(INDEX(Transactions!$B$5:$B$5004,$K17)="","",INDEX(Transactions!$B$5:$B$5004,$K17))) | E17: =IF($K17="","",IF(INDEX(Transactions!$C$5:$C$5004,$K17)="","",INDEX(Transactions!$C$5:$C$5004,$K17))) | F17: =IF($K17="","",IF(INDEX(Transactions!$D$5:$D$5004,$K17)="","",INDEX(Transactions!$D$5:$D$5004,$K17))) | G17: =IF($K17="","",IF(INDEX(Transactions!$E$5:$E$5004,$K17)="","",INDEX(Transactions!$E$5:$E$5004,$K17))) | H17: =IF($K17="","",IF(INDEX(Transactions!$F$5:$F$5004,$K17)="","",INDEX(Transactions!$F$5:$F$5004,$K17))) | I17: =IF($K17="","",IF(INDEX(Transactions!$G$5:$G$5004,$K17)="","",INDEX(Transactions!$G$5:$G$5004,$K17))) | K17: =IFERROR(MATCH(3,Transactions!$H$5:$H$5004,0),"")
B18: =IF($K18="","",4) | C18: =IF($K18="","",IF(INDEX(Transactions!$A$5:$A$5004,$K18)="","",INDEX(Transactions!$A$5:$A$5004,$K18))) | D18: =IF($K18="","",IF(INDEX(Transactions!$B$5:$B$5004,$K18)="","",INDEX(Transactions!$B$5:$B$5004,$K18))) | E18: =IF($K18="","",IF(INDEX(Transactions!$C$5:$C$5004,$K18)="","",INDEX(Transactions!$C$5:$C$5004,$K18))) | F18: =IF($K18="","",IF(INDEX(Transactions!$D$5:$D$5004,$K18)="","",INDEX(Transactions!$D$5:$D$5004,$K18))) | G18: =IF($K18="","",IF(INDEX(Transactions!$E$5:$E$5004,$K18)="","",INDEX(Transactions!$E$5:$E$5004,$K18))) | H18: =IF($K18="","",IF(INDEX(Transactions!$F$5:$F$5004,$K18)="","",INDEX(Transactions!$F$5:$F$5004,$K18))) | I18: =IF($K18="","",IF(INDEX(Transactions!$G$5:$G$5004,$K18)="","",INDEX(Transactions!$G$5:$G$5004,$K18))) | K18: =IFERROR(MATCH(4,Transactions!$H$5:$H$5004,0),"")
B19: =IF($K19="","",5) | C19: =IF($K19="","",IF(INDEX(Transactions!$A$5:$A$5004,$K19)="","",INDEX(Transactions!$A$5:$A$5004,$K19))) | D19: =IF($K19="","",IF(INDEX(Transactions!$B$5:$B$5004,$K19)="","",INDEX(Transactions!$B$5:$B$5004,$K19))) | E19: =IF($K19="","",IF(INDEX(Transactions!$C$5:$C$5004,$K19)="","",INDEX(Transactions!$C$5:$C$5004,$K19))) | F19: =IF($K19="","",IF(INDEX(Transactions!$D$5:$D$5004,$K19)="","",INDEX(Transactions!$D$5:$D$5004,$K19))) | G19: =IF($K19="","",IF(INDEX(Transactions!$E$5:$E$5004,$K19)="","",INDEX(Transactions!$E$5:$E$5004,$K19))) | H19: =IF($K19="","",IF(INDEX(Transactions!$F$5:$F$5004,$K19)="","",INDEX(Transactions!$F$5:$F$5004,$K19))) | I19: =IF($K19="","",IF(INDEX(Transactions!$G$5:$G$5004,$K19)="","",INDEX(Transactions!$G$5:$G$5004,$K19))) | K19: =IFERROR(MATCH(5,Transactions!$H$5:$H$5004,0),"")
B20: =IF($K20="","",6) | C20: =IF($K20="","",IF(INDEX(Transactions!$A$5:$A$5004,$K20)="","",INDEX(Transactions!$A$5:$A$5004,$K20))) | D20: =IF($K20="","",IF(INDEX(Transactions!$B$5:$B$5004,$K20)="","",INDEX(Transactions!$B$5:$B$5004,$K20))) | E20: =IF($K20="","",IF(INDEX(Transactions!$C$5:$C$5004,$K20)="","",INDEX(Transactions!$C$5:$C$5004,$K20))) | F20: =IF($K20="","",IF(INDEX(Transactions!$D$5:$D$5004,$K20)="","",INDEX(Transactions!$D$5:$D$5004,$K20))) | G20: =IF($K20="","",IF(INDEX(Transactions!$E$5:$E$5004,$K20)="","",INDEX(Transactions!$E$5:$E$5004,$K20))) | H20: =IF($K20="","",IF(INDEX(Transactions!$F$5:$F$5004,$K20)="","",INDEX(Transactions!$F$5:$F$5004,$K20))) | I20: =IF($K20="","",IF(INDEX(Transactions!$G$5:$G$5004,$K20)="","",INDEX(Transactions!$G$5:$G$5004,$K20))) | K20: =IFERROR(MATCH(6,Transactions!$H$5:$H$5004,0),"")
B21: =IF($K21="","",7) | C21: =IF($K21="","",IF(INDEX(Transactions!$A$5:$A$5004,$K21)="","",INDEX(Transactions!$A$5:$A$5004,$K21))) | D21: =IF($K21="","",IF(INDEX(Transactions!$B$5:$B$5004,$K21)="","",INDEX(Transactions!$B$5:$B$5004,$K21))) | E21: =IF($K21="","",IF(INDEX(Transactions!$C$5:$C$5004,$K21)="","",INDEX(Transactions!$C$5:$C$5004,$K21))) | F21: =IF($K21="","",IF(INDEX(Transactions!$D$5:$D$5004,$K21)="","",INDEX(Transactions!$D$5:$D$5004,$K21))) | G21: =IF($K21="","",IF(INDEX(Transactions!$E$5:$E$5004,$K21)="","",INDEX(Transactions!$E$5:$E$5004,$K21))) | H21: =IF($K21="","",IF(INDEX(Transactions!$F$5:$F$5004,$K21)="","",INDEX(Transactions!$F$5:$F$5004,$K21))) | I21: =IF($K21="","",IF(INDEX(Transactions!$G$5:$G$5004,$K21)="","",INDEX(Transactions!$G$5:$G$5004,$K21))) | K21: =IFERROR(MATCH(7,Transactions!$H$5:$H$5004,0),"")
B22: =IF($K22="","",8) | C22: =IF($K22="","",IF(INDEX(Transactions!$A$5:$A$5004,$K22)="","",INDEX(Transactions!$A$5:$A$5004,$K22))) | D22: =IF($K22="","",IF(INDEX(Transactions!$B$5:$B$5004,$K22)="","",INDEX(Transactions!$B$5:$B$5004,$K22))) | E22: =IF($K22="","",IF(INDEX(Transactions!$C$5:$C$5004,$K22)="","",INDEX(Transactions!$C$5:$C$5004,$K22))) | F22: =IF($K22="","",IF(INDEX(Transactions!$D$5:$D$5004,$K22)="","",INDEX(Transactions!$D$5:$D$5004,$K22))) | G22: =IF($K22="","",IF(INDEX(Transactions!$E$5:$E$5004,$K22)="","",INDEX(Transactions!$E$5:$E$5004,$K22))) | H22: =IF($K22="","",IF(INDEX(Transactions!$F$5:$F$5004,$K22)="","",INDEX(Transactions!$F$5:$F$5004,$K22))) | I22: =IF($K22="","",IF(INDEX(Transactions!$G$5:$G$5004,$K22)="","",INDEX(Transactions!$G$5:$G$5004,$K22))) | K22: =IFERROR(MATCH(8,Transactions!$H$5:$H$5004,0),"")
B23: =IF($K23="","",9) | C23: =IF($K23="","",IF(INDEX(Transactions!$A$5:$A$5004,$K23)="","",INDEX(Transactions!$A$5:$A$5004,$K23))) | D23: =IF($K23="","",IF(INDEX(Transactions!$B$5:$B$5004,$K23)="","",INDEX(Transactions!$B$5:$B$5004,$K23))) | E23: =IF($K23="","",IF(INDEX(Transactions!$C$5:$C$5004,$K23)="","",INDEX(Transactions!$C$5:$C$5004,$K23))) | F23: =IF($K23="","",IF(INDEX(Transactions!$D$5:$D$5004,$K23)="","",INDEX(Transactions!$D$5:$D$5004,$K23))) | G23: =IF($K23="","",IF(INDEX(Transactions!$E$5:$E$5004,$K23)="","",INDEX(Transactions!$E$5:$E$5004,$K23))) | H23: =IF($K23="","",IF(INDEX(Transactions!$F$5:$F$5004,$K23)="","",INDEX(Transactions!$F$5:$F$5004,$K23))) | I23: =IF($K23="","",IF(INDEX(Transactions!$G$5:$G$5004,$K23)="","",INDEX(Transactions!$G$5:$G$5004,$K23))) | K23: =IFERROR(MATCH(9,Transactions!$H$5:$H$5004,0),"")
B24: =IF($K24="","",10) | C24: =IF($K24="","",IF(INDEX(Transactions!$A$5:$A$5004,$K24)="","",INDEX(Transactions!$A$5:$A$5004,$K24))) | D24: =IF($K24="","",IF(INDEX(Transactions!$B$5:$B$5004,$K24)="","",INDEX(Transactions!$B$5:$B$5004,$K24))) | E24: =IF($K24="","",IF(INDEX(Transactions!$C$5:$C$5004,$K24)="","",INDEX(Transactions!$C$5:$C$5004,$K24))) | F24: =IF($K24="","",IF(INDEX(Transactions!$D$5:$D$5004,$K24)="","",INDEX(Transactions!$D$5:$D$5004,$K24))) | G24: =IF($K24="","",IF(INDEX(Transactions!$E$5:$E$5004,$K24)="","",INDEX(Transactions!$E$5:$E$5004,$K24))) | H24: =IF($K24="","",IF(INDEX(Transactions!$F$5:$F$5004,$K24)="","",INDEX(Transactions!$F$5:$F$5004,$K24))) | I24: =IF($K24="","",IF(INDEX(Transactions!$G$5:$G$5004,$K24)="","",INDEX(Transactions!$G$5:$G$5004,$K24))) | K24: =IFERROR(MATCH(10,Transactions!$H$5:$H$5004,0),"")
B25: =IF($K25="","",11) | C25: =IF($K25="","",IF(INDEX(Transactions!$A$5:$A$5004,$K25)="","",INDEX(Transactions!$A$5:$A$5004,$K25))) | D25: =IF($K25="","",IF(INDEX(Transactions!$B$5:$B$5004,$K25)="","",INDEX(Transactions!$B$5:$B$5004,$K25))) | E25: =IF($K25="","",IF(INDEX(Transactions!$C$5:$C$5004,$K25)="","",INDEX(Transactions!$C$5:$C$5004,$K25))) | F25: =IF($K25="","",IF(INDEX(Transactions!$D$5:$D$5004,$K25)="","",INDEX(Transactions!$D$5:$D$5004,$K25))) | G25: =IF($K25="","",IF(INDEX(Transactions!$E$5:$E$5004,$K25)="","",INDEX(Transactions!$E$5:$E$5004,$K25))) | H25: =IF($K25="","",IF(INDEX(Transactions!$F$5:$F$5004,$K25)="","",INDEX(Transactions!$F$5:$F$5004,$K25))) | I25: =IF($K25="","",IF(INDEX(Transactions!$G$5:$G$5004,$K25)="","",INDEX(Transactions!$G$5:$G$5004,$K25))) | K25: =IFERROR(MATCH(11,Transactions!$H$5:$H$5004,0),"")
B26: =IF($K26="","",12) | C26: =IF($K26="","",IF(INDEX(Transactions!$A$5:$A$5004,$K26)="","",INDEX(Transactions!$A$5:$A$5004,$K26))) | D26: =IF($K26="","",IF(INDEX(Transactions!$B$5:$B$5004,$K26)="","",INDEX(Transactions!$B$5:$B$5004,$K26))) | E26: =IF($K26="","",IF(INDEX(Transactions!$C$5:$C$5004,$K26)="","",INDEX(Transactions!$C$5:$C$5004,$K26))) | F26: =IF($K26="","",IF(INDEX(Transactions!$D$5:$D$5004,$K26)="","",INDEX(Transactions!$D$5:$D$5004,$K26))) | G26: =IF($K26="","",IF(INDEX(Transactions!$E$5:$E$5004,$K26)="","",INDEX(Transactions!$E$5:$E$5004,$K26))) | H26: =IF($K26="","",IF(INDEX(Transactions!$F$5:$F$5004,$K26)="","",INDEX(Transactions!$F$5:$F$5004,$K26))) | I26: =IF($K26="","",IF(INDEX(Transactions!$G$5:$G$5004,$K26)="","",INDEX(Transactions!$G$5:$G$5004,$K26))) | K26: =IFERROR(MATCH(12,Transactions!$H$5:$H$5004,0),"")
B27: =IF($K27="","",13) | C27: =IF($K27="","",IF(INDEX(Transactions!$A$5:$A$5004,$K27)="","",INDEX(Transactions!$A$5:$A$5004,$K27))) | D27: =IF($K27="","",IF(INDEX(Transactions!$B$5:$B$5004,$K27)="","",INDEX(Transactions!$B$5:$B$5004,$K27))) | E27: =IF($K27="","",IF(INDEX(Transactions!$C$5:$C$5004,$K27)="","",INDEX(Transactions!$C$5:$C$5004,$K27))) | F27: =IF($K27="","",IF(INDEX(Transactions!$D$5:$D$5004,$K27)="","",INDEX(Transactions!$D$5:$D$5004,$K27))) | G27: =IF($K27="","",IF(INDEX(Transactions!$E$5:$E$5004,$K27)="","",INDEX(Transactions!$E$5:$E$5004,$K27))) | H27: =IF($K27="","",IF(INDEX(Transactions!$F$5:$F$5004,$K27)="","",INDEX(Transactions!$F$5:$F$5004,$K27))) | I27: =IF($K27="","",IF(INDEX(Transactions!$G$5:$G$5004,$K27)="","",INDEX(Transactions!$G$5:$G$5004,$K27))) | K27: =IFERROR(MATCH(13,Transactions!$H$5:$H$5004,0),"")
B28: =IF($K28="","",14) | C28: =IF($K28="","",IF(INDEX(Transactions!$A$5:$A$5004,$K28)="","",INDEX(Transactions!$A$5:$A$5004,$K28))) | D28: =IF($K28="","",IF(INDEX(Transactions!$B$5:$B$5004,$K28)="","",INDEX(Transactions!$B$5:$B$5004,$K28))) | E28: =IF($K28="","",IF(INDEX(Transactions!$C$5:$C$5004,$K28)="","",INDEX(Transactions!$C$5:$C$5004,$K28))) | F28: =IF($K28="","",IF(INDEX(Transactions!$D$5:$D$5004,$K28)="","",INDEX(Transactions!$D$5:$D$5004,$K28))) | G28: =IF($K28="","",IF(INDEX(Transactions!$E$5:$E$5004,$K28)="","",INDEX(Transactions!$E$5:$E$5004,$K28))) | H28: =IF($K28="","",IF(INDEX(Transactions!$F$5:$F$5004,$K28)="","",INDEX(Transactions!$F$5:$F$5004,$K28))) | I28: =IF($K28="","",IF(INDEX(Transactions!$G$5:$G$5004,$K28)="","",INDEX(Transactions!$G$5:$G$5004,$K28))) | K28: =IFERROR(MATCH(14,Transactions!$H$5:$H$5004,0),"")
B29: =IF($K29="","",15) | C29: =IF($K29="","",IF(INDEX(Transactions!$A$5:$A$5004,$K29)="","",INDEX(Transactions!$A$5:$A$5004,$K29))) | D29: =IF($K29="","",IF(INDEX(Transactions!$B$5:$B$5004,$K29)="","",INDEX(Transactions!$B$5:$B$5004,$K29))) | E29: =IF($K29="","",IF(INDEX(Transactions!$C$5:$C$5004,$K29)="","",INDEX(Transactions!$C$5:$C$5004,$K29))) | F29: =IF($K29="","",IF(INDEX(Transactions!$D$5:$D$5004,$K29)="","",INDEX(Transactions!$D$5:$D$5004,$K29))) | G29: =IF($K29="","",IF(INDEX(Transactions!$E$5:$E$5004,$K29)="","",INDEX(Transactions!$E$5:$E$5004,$K29))) | H29: =IF($K29="","",IF(INDEX(Transactions!$F$5:$F$5004,$K29)="","",INDEX(Transactions!$F$5:$F$5004,$K29))) | I29: =IF($K29="","",IF(INDEX(Transactions!$G$5:$G$5004,$K29)="","",INDEX(Transactions!$G$5:$G$5004,$K29))) | K29: =IFERROR(MATCH(15,Transactions!$H$5:$H$5004,0),"")
B30: =IF($K30="","",16) | C30: =IF($K30="","",IF(INDEX(Transactions!$A$5:$A$5004,$K30)="","",INDEX(Transactions!$A$5:$A$5004,$K30))) | D30: =IF($K30="","",IF(INDEX(Transactions!$B$5:$B$5004,$K30)="","",INDEX(Transactions!$B$5:$B$5004,$K30))) | E30: =IF($K30="","",IF(INDEX(Transactions!$C$5:$C$5004,$K30)="","",INDEX(Transactions!$C$5:$C$5004,$K30))) | F30: =IF($K30="","",IF(INDEX(Transactions!$D$5:$D$5004,$K30)="","",INDEX(Transactions!$D$5:$D$5004,$K30))) | G30: =IF($K30="","",IF(INDEX(Transactions!$E$5:$E$5004,$K30)="","",INDEX(Transactions!$E$5:$E$5004,$K30))) | H30: =IF($K30="","",IF(INDEX(Transactions!$F$5:$F$5004,$K30)="","",INDEX(Transactions!$F$5:$F$5004,$K30))) | I30: =IF($K30="","",IF(INDEX(Transactions!$G$5:$G$5004,$K30)="","",INDEX(Transactions!$G$5:$G$5004,$K30))) | K30: =IFERROR(MATCH(16,Transactions!$H$5:$H$5004,0),"")
B31: =IF($K31="","",17) | C31: =IF($K31="","",IF(INDEX(Transactions!$A$5:$A$5004,$K31)="","",INDEX(Transactions!$A$5:$A$5004,$K31))) | D31: =IF($K31="","",IF(INDEX(Transactions!$B$5:$B$5004,$K31)="","",INDEX(Transactions!$B$5:$B$5004,$K31))) | E31: =IF($K31="","",IF(INDEX(Transactions!$C$5:$C$5004,$K31)="","",INDEX(Transactions!$C$5:$C$5004,$K31))) | F31: =IF($K31="","",IF(INDEX(Transactions!$D$5:$D$5004,$K31)="","",INDEX(Transactions!$D$5:$D$5004,$K31))) | G31: =IF($K31="","",IF(INDEX(Transactions!$E$5:$E$5004,$K31)="","",INDEX(Transactions!$E$5:$E$5004,$K31))) | H31: =IF($K31="","",IF(INDEX(Transactions!$F$5:$F$5004,$K31)="","",INDEX(Transactions!$F$5:$F$5004,$K31))) | I31: =IF($K31="","",IF(INDEX(Transactions!$G$5:$G$5004,$K31)="","",INDEX(Transactions!$G$5:$G$5004,$K31))) | K31: =IFERROR(MATCH(17,Transactions!$H$5:$H$5004,0),"")
B32: =IF($K32="","",18) | C32: =IF($K32="","",IF(INDEX(Transactions!$A$5:$A$5004,$K32)="","",INDEX(Transactions!$A$5:$A$5004,$K32))) | D32: =IF($K32="","",IF(INDEX(Transactions!$B$5:$B$5004,$K32)="","",INDEX(Transactions!$B$5:$B$5004,$K32))) | E32: =IF($K32="","",IF(INDEX(Transactions!$C$5:$C$5004,$K32)="","",INDEX(Transactions!$C$5:$C$5004,$K32))) | F32: =IF($K32="","",IF(INDEX(Transactions!$D$5:$D$5004,$K32)="","",INDEX(Transactions!$D$5:$D$5004,$K32))) | G32: =IF($K32="","",IF(INDEX(Transactions!$E$5:$E$5004,$K32)="","",INDEX(Transactions!$E$5:$E$5004,$K32))) | H32: =IF($K32="","",IF(INDEX(Transactions!$F$5:$F$5004,$K32)="","",INDEX(Transactions!$F$5:$F$5004,$K32))) | I32: =IF($K32="","",IF(INDEX(Transactions!$G$5:$G$5004,$K32)="","",INDEX(Transactions!$G$5:$G$5004,$K32))) | K32: =IFERROR(MATCH(18,Transactions!$H$5:$H$5004,0),"")
B33: =IF($K33="","",19) | C33: =IF($K33="","",IF(INDEX(Transactions!$A$5:$A$5004,$K33)="","",INDEX(Transactions!$A$5:$A$5004,$K33))) | D33: =IF($K33="","",IF(INDEX(Transactions!$B$5:$B$5004,$K33)="","",INDEX(Transactions!$B$5:$B$5004,$K33))) | E33: =IF($K33="","",IF(INDEX(Transactions!$C$5:$C$5004,$K33)="","",INDEX(Transactions!$C$5:$C$5004,$K33))) | F33: =IF($K33="","",IF(INDEX(Transactions!$D$5:$D$5004,$K33)="","",INDEX(Transactions!$D$5:$D$5004,$K33))) | G33: =IF($K33="","",IF(INDEX(Transactions!$E$5:$E$5004,$K33)="","",INDEX(Transactions!$E$5:$E$5004,$K33))) | H33: =IF($K33="","",IF(INDEX(Transactions!$F$5:$F$5004,$K33)="","",INDEX(Transactions!$F$5:$F$5004,$K33))) | I33: =IF($K33="","",IF(INDEX(Transactions!$G$5:$G$5004,$K33)="","",INDEX(Transactions!$G$5:$G$5004,$K33))) | K33: =IFERROR(MATCH(19,Transactions!$H$5:$H$5004,0),"")
B34: =IF($K34="","",20) | C34: =IF($K34="","",IF(INDEX(Transactions!$A$5:$A$5004,$K34)="","",INDEX(Transactions!$A$5:$A$5004,$K34))) | D34: =IF($K34="","",IF(INDEX(Transactions!$B$5:$B$5004,$K34)="","",INDEX(Transactions!$B$5:$B$5004,$K34))) | E34: =IF($K34="","",IF(INDEX(Transactions!$C$5:$C$5004,$K34)="","",INDEX(Transactions!$C$5:$C$5004,$K34))) | F34: =IF($K34="","",IF(INDEX(Transactions!$D$5:$D$5004,$K34)="","",INDEX(Transactions!$D$5:$D$5004,$K34))) | G34: =IF($K34="","",IF(INDEX(Transactions!$E$5:$E$5004,$K34)="","",INDEX(Transactions!$E$5:$E$5004,$K34))) | H34: =IF($K34="","",IF(INDEX(Transactions!$F$5:$F$5004,$K34)="","",INDEX(Transactions!$F$5:$F$5004,$K34))) | I34: =IF($K34="","",IF(INDEX(Transactions!$G$5:$G$5004,$K34)="","",INDEX(Transactions!$G$5:$G$5004,$K34))) | K34: =IFERROR(MATCH(20,Transactions!$H$5:$H$5004,0),"")
B35: =IF($K35="","",21) | C35: =IF($K35="","",IF(INDEX(Transactions!$A$5:$A$5004,$K35)="","",INDEX(Transactions!$A$5:$A$5004,$K35))) | D35: =IF($K35="","",IF(INDEX(Transactions!$B$5:$B$5004,$K35)="","",INDEX(Transactions!$B$5:$B$5004,$K35))) | E35: =IF($K35="","",IF(INDEX(Transactions!$C$5:$C$5004,$K35)="","",INDEX(Transactions!$C$5:$C$5004,$K35))) | F35: =IF($K35="","",IF(INDEX(Transactions!$D$5:$D$5004,$K35)="","",INDEX(Transactions!$D$5:$D$5004,$K35))) | G35: =IF($K35="","",IF(INDEX(Transactions!$E$5:$E$5004,$K35)="","",INDEX(Transactions!$E$5:$E$5004,$K35))) | H35: =IF($K35="","",IF(INDEX(Transactions!$F$5:$F$5004,$K35)="","",INDEX(Transactions!$F$5:$F$5004,$K35))) | I35: =IF($K35="","",IF(INDEX(Transactions!$G$5:$G$5004,$K35)="","",INDEX(Transactions!$G$5:$G$5004,$K35))) | K35: =IFERROR(MATCH(21,Transactions!$H$5:$H$5004,0),"")
B36: =IF($K36="","",22) | C36: =IF($K36="","",IF(INDEX(Transactions!$A$5:$A$5004,$K36)="","",INDEX(Transactions!$A$5:$A$5004,$K36))) | D36: =IF($K36="","",IF(INDEX(Transactions!$B$5:$B$5004,$K36)="","",INDEX(Transactions!$B$5:$B$5004,$K36))) | E36: =IF($K36="","",IF(INDEX(Transactions!$C$5:$C$5004,$K36)="","",INDEX(Transactions!$C$5:$C$5004,$K36))) | F36: =IF($K36="","",IF(INDEX(Transactions!$D$5:$D$5004,$K36)="","",INDEX(Transactions!$D$5:$D$5004,$K36))) | G36: =IF($K36="","",IF(INDEX(Transactions!$E$5:$E$5004,$K36)="","",INDEX(Transactions!$E$5:$E$5004,$K36))) | H36: =IF($K36="","",IF(INDEX(Transactions!$F$5:$F$5004,$K36)="","",INDEX(Transactions!$F$5:$F$5004,$K36))) | I36: =IF($K36="","",IF(INDEX(Transactions!$G$5:$G$5004,$K36)="","",INDEX(Transactions!$G$5:$G$5004,$K36))) | K36: =IFERROR(MATCH(22,Transactions!$H$5:$H$5004,0),"")
B37: =IF($K37="","",23) | C37: =IF($K37="","",IF(INDEX(Transactions!$A$5:$A$5004,$K37)="","",INDEX(Transactions!$A$5:$A$5004,$K37))) | D37: =IF($K37="","",IF(INDEX(Transactions!$B$5:$B$5004,$K37)="","",INDEX(Transactions!$B$5:$B$5004,$K37))) | E37: =IF($K37="","",IF(INDEX(Transactions!$C$5:$C$5004,$K37)="","",INDEX(Transactions!$C$5:$C$5004,$K37))) | F37: =IF($K37="","",IF(INDEX(Transactions!$D$5:$D$5004,$K37)="","",INDEX(Transactions!$D$5:$D$5004,$K37))) | G37: =IF($K37="","",IF(INDEX(Transactions!$E$5:$E$5004,$K37)="","",INDEX(Transactions!$E$5:$E$5004,$K37))) | H37: =IF($K37="","",IF(INDEX(Transactions!$F$5:$F$5004,$K37)="","",INDEX(Transactions!$F$5:$F$5004,$K37))) | I37: =IF($K37="","",IF(INDEX(Transactions!$G$5:$G$5004,$K37)="","",INDEX(Transactions!$G$5:$G$5004,$K37))) | K37: =IFERROR(MATCH(23,Transactions!$H$5:$H$5004,0),"")
B38: =IF($K38="","",24) | C38: =IF($K38="","",IF(INDEX(Transactions!$A$5:$A$5004,$K38)="","",INDEX(Transactions!$A$5:$A$5004,$K38))) | D38: =IF($K38="","",IF(INDEX(Transactions!$B$5:$B$5004,$K38)="","",INDEX(Transactions!$B$5:$B$5004,$K38))) | E38: =IF($K38="","",IF(INDEX(Transactions!$C$5:$C$5004,$K38)="","",INDEX(Transactions!$C$5:$C$5004,$K38))) | F38: =IF($K38="","",IF(INDEX(Transactions!$D$5:$D$5004,$K38)="","",INDEX(Transactions!$D$5:$D$5004,$K38))) | G38: =IF($K38="","",IF(INDEX(Transactions!$E$5:$E$5004,$K38)="","",INDEX(Transactions!$E$5:$E$5004,$K38))) | H38: =IF($K38="","",IF(INDEX(Transactions!$F$5:$F$5004,$K38)="","",INDEX(Transactions!$F$5:$F$5004,$K38))) | I38: =IF($K38="","",IF(INDEX(Transactions!$G$5:$G$5004,$K38)="","",INDEX(Transactions!$G$5:$G$5004,$K38))) | K38: =IFERROR(MATCH(24,Transactions!$H$5:$H$5004,0),"")
B39: =IF($K39="","",25) | C39: =IF($K39="","",IF(INDEX(Transactions!$A$5:$A$5004,$K39)="","",INDEX(Transactions!$A$5:$A$5004,$K39))) | D39: =IF($K39="","",IF(INDEX(Transactions!$B$5:$B$5004,$K39)="","",INDEX(Transactions!$B$5:$B$5004,$K39))) | E39: =IF($K39="","",IF(INDEX(Transactions!$C$5:$C$5004,$K39)="","",INDEX(Transactions!$C$5:$C$5004,$K39))) | F39: =IF($K39="","",IF(INDEX(Transactions!$D$5:$D$5004,$K39)="","",INDEX(Transactions!$D$5:$D$5004,$K39))) | G39: =IF($K39="","",IF(INDEX(Transactions!$E$5:$E$5004,$K39)="","",INDEX(Transactions!$E$5:$E$5004,$K39))) | H39: =IF($K39="","",IF(INDEX(Transactions!$F$5:$F$5004,$K39)="","",INDEX(Transactions!$F$5:$F$5004,$K39))) | I39: =IF($K39="","",IF(INDEX(Transactions!$G$5:$G$5004,$K39)="","",INDEX(Transactions!$G$5:$G$5004,$K39))) | K39: =IFERROR(MATCH(25,Transactions!$H$5:$H$5004,0),"")
B40: =IF($K40="","",26) | C40: =IF($K40="","",IF(INDEX(Transactions!$A$5:$A$5004,$K40)="","",INDEX(Transactions!$A$5:$A$5004,$K40))) | D40: =IF($K40="","",IF(INDEX(Transactions!$B$5:$B$5004,$K40)="","",INDEX(Transactions!$B$5:$B$5004,$K40))) | E40: =IF($K40="","",IF(INDEX(Transactions!$C$5:$C$5004,$K40)="","",INDEX(Transactions!$C$5:$C$5004,$K40))) | F40: =IF($K40="","",IF(INDEX(Transactions!$D$5:$D$5004,$K40)="","",INDEX(Transactions!$D$5:$D$5004,$K40))) | G40: =IF($K40="","",IF(INDEX(Transactions!$E$5:$E$5004,$K40)="","",INDEX(Transactions!$E$5:$E$5004,$K40))) | H40: =IF($K40="","",IF(INDEX(Transactions!$F$5:$F$5004,$K40)="","",INDEX(Transactions!$F$5:$F$5004,$K40))) | I40: =IF($K40="","",IF(INDEX(Transactions!$G$5:$G$5004,$K40)="","",INDEX(Transactions!$G$5:$G$5004,$K40))) | K40: =IFERROR(MATCH(26,Transactions!$H$5:$H$5004,0),"")
B41: =IF($K41="","",27) | C41: =IF($K41="","",IF(INDEX(Transactions!$A$5:$A$5004,$K41)="","",INDEX(Transactions!$A$5:$A$5004,$K41))) | D41: =IF($K41="","",IF(INDEX(Transactions!$B$5:$B$5004,$K41)="","",INDEX(Transactions!$B$5:$B$5004,$K41))) | E41: =IF($K41="","",IF(INDEX(Transactions!$C$5:$C$5004,$K41)="","",INDEX(Transactions!$C$5:$C$5004,$K41))) | F41: =IF($K41="","",IF(INDEX(Transactions!$D$5:$D$5004,$K41)="","",INDEX(Transactions!$D$5:$D$5004,$K41))) | G41: =IF($K41="","",IF(INDEX(Transactions!$E$5:$E$5004,$K41)="","",INDEX(Transactions!$E$5:$E$5004,$K41))) | H41: =IF($K41="","",IF(INDEX(Transactions!$F$5:$F$5004,$K41)="","",INDEX(Transactions!$F$5:$F$5004,$K41))) | I41: =IF($K41="","",IF(INDEX(Transactions!$G$5:$G$5004,$K41)="","",INDEX(Transactions!$G$5:$G$5004,$K41))) | K41: =IFERROR(MATCH(27,Transactions!$H$5:$H$5004,0),"")
B42: =IF($K42="","",28) | C42: =IF($K42="","",IF(INDEX(Transactions!$A$5:$A$5004,$K42)="","",INDEX(Transactions!$A$5:$A$5004,$K42))) | D42: =IF($K42="","",IF(INDEX(Transactions!$B$5:$B$5004,$K42)="","",INDEX(Transactions!$B$5:$B$5004,$K42))) | E42: =IF($K42="","",IF(INDEX(Transactions!$C$5:$C$5004,$K42)="","",INDEX(Transactions!$C$5:$C$5004,$K42))) | F42: =IF($K42="","",IF(INDEX(Transactions!$D$5:$D$5004,$K42)="","",INDEX(Transactions!$D$5:$D$5004,$K42))) | G42: =IF($K42="","",IF(INDEX(Transactions!$E$5:$E$5004,$K42)="","",INDEX(Transactions!$E$5:$E$5004,$K42))) | H42: =IF($K42="","",IF(INDEX(Transactions!$F$5:$F$5004,$K42)="","",INDEX(Transactions!$F$5:$F$5004,$K42))) | I42: =IF($K42="","",IF(INDEX(Transactions!$G$5:$G$5004,$K42)="","",INDEX(Transactions!$G$5:$G$5004,$K42))) | K42: =IFERROR(MATCH(28,Transactions!$H$5:$H$5004,0),"")
